Workbook

Sheet Master
A1: ID | B1: Type | C1: Title | D1: Catalog ID | E1: Category | F1: Division | G1: Requester / Regulator | H1: Owner | I1: Doer | J1: Support | K1: Whole team | L1: Letter no. | M1: Letter code | N1: Request reference | O1: Start / received | P1: Due date | Q1: Submitted date | R1: Priority | S1: Effort | T1: Weight | U1: Progress | V1: Status | W1: Last updated | X1: Link | Y1: Send to | Z1: Notes | AA1: Flag | AB1: Source | AC1: Routing note
A2: EX-1 | B2: Reporting | C2: [EXAMPLE] ATMR Kredit Q3 | D2: FIN-ATMR | E2: BRI Pusat | F2: Policy and Risk | G2: BRI Pusat | H2: Leila | I2: Leila | L2: B.91.e-EMR/IRM/10/2026 | M2: EMR/IRM | N2: B.91.e-EMR/IRM/10/2026 | O2: 46302 | P2: 46310 | Q2: 46307 | T2: =IFERROR(VLOOKUP("Effort: "&IF(S2="","Medium",S2),Config!$A$2:$B$4,2,FALSE()),Config!$B$3) -> 2 | U2: 1 | V2: Done | Y2: Email: ayu.putu.alika.pramesvari@brilian.bri.co.id | Z2: Example row showing the format. Delete before go-live. | AB2: Copied from Timeline GRC - Reporting #115
A3: EX-2 | B3: Project | C3: [EXAMPLE] Risk Mapping FlexM | E3: Others | H3: Gwen | I3: Gwen | O3: 46209 | P3: 46235 | R3: Medium | T3: =IFERROR(VLOOKUP("Effort: "&IF(S3="","Medium",S3),Config!$A$2:$B$4,2,FALSE()),Config!$B$3) -> 2 | U3: 1 | V3: Done | X3: RemitGo x FlexM Risk Identification and Treatment.xlsx | Z3: Example row showing the format. Delete before go-live. | AB3: Copied from Timeline GRC - Tasks #18
A4: EX-3 | B4: PRD assessment | C4: [EXAMPLE] remitgo Promo Code | E4: Remitgo | F4: Policy and Risk | G4: Ko Kenneth | H4: Gwen | I4: Gwen | P4: 46297 | S4: Medium | T4: =IFERROR(VLOOKUP("Effort: "&IF(S4="","Medium",S4),Config!$A$2:$B$4,2,FALSE()),Config!$B$3) -> 2 | U4: 1 | V4: Done | X4: PRD promo code; RA004_Promo Code Engine (Internal Dashboard + remit.go!) | Z4: Example row showing the format. Delete before go-live. | AB4: Copied from Timeline GRC - PRD RA004

Sheet Staff
A1: Staff ID | B1: Name | C1: Spellings found | D1: Main division | E1: Role | F1: Suggested role (from data) | G1: Internship end date | H1: Capacity (1 = full time) | I1: Open (as doer) | J1: Open as support | K1: Overdue (as owner) | L1: Weighted open load | M1: Load vs capacity | N1: Owns catalog reports | O1: Email
A2: S01 | B2: Stesya | C2: Ste, Stes, Stesya | D2: Policy and Risk | H2: 1 | I2: =COUNTIFS(Master!$I$2:$I$2000,B2,Master!$V$2:$V$2000,"<>Done",Master!$V$2:$V$2000,"<>Cancelled",Master!$C$2:$C$2000,"<>") -> 0 | J2: =SUMPRODUCT(ISNUMBER(SEARCH(B2,Master!$J$2:$J$2000))*(Master!$V$2:$V$2000<>"Done")*(Master!$V$2:$V$2000<>"Cancelled")*(Master!$C$2:$C$2000<>"")) -> 0 | K2: =COUNTIFS(Master!$H$2:$H$2000,B2,Master!$V$2:$V$2000,"<>Done",Master!$V$2:$V$2000,"<>Cancelled",Master!$P$2:$P$2000,"<"&TODAY()) -> 0 | L2: =SUMPRODUCT((Master!$I$2:$I$2000=B2)*(Master!$V$2:$V$2000<>"Done")*(Master!$V$2:$V$2000<>"Cancelled")*Master!$T$2:$T$2000)+Config!$B$5*SUMPRODUCT(ISNUMBER(SEARCH(B2,Master!$J$2:$J$2000))*(Master!$V$2:$V$2000<>"Done")*(Master!$V$2:$V$2000<>"Cancelled")*Master!$T$2:$T$2000) -> 0 | M2: =IF(OR(H2="",H2=0),"",L2/H2) -> 0 | N2: =COUNTIF(Catalog!$F$2:$F$200,B2) -> 13
A3: S02 | B3: Cia | C3: Ci, Cia | D3: Finance | F3: Intern (runs an intern project) | H3: 1 | I3: =COUNTIFS(Master!$I$2:$I$2000,B3,Master!$V$2:$V$2000,"<>Done",Master!$V$2:$V$2000,"<>Cancelled",Master!$C$2:$C$2000,"<>") -> 0 | J3: =SUMPRODUCT(ISNUMBER(SEARCH(B3,Master!$J$2:$J$2000))*(Master!$V$2:$V$2000<>"Done")*(Master!$V$2:$V$2000<>"Cancelled")*(Master!$C$2:$C$2000<>"")) -> 0 | K3: =COUNTIFS(Master!$H$2:$H$2000,B3,Master!$V$2:$V$2000,"<>Done",Master!$V$2:$V$2000,"<>Cancelled",Master!$P$2:$P$2000,"<"&TODAY()) -> 0 | L3: =SUMPRODUCT((Master!$I$2:$I$2000=B3)*(Master!$V$2:$V$2000<>"Done")*(Master!$V$2:$V$2000<>"Cancelled")*Master!$T$2:$T$2000)+Config!$B$5*SUMPRODUCT(ISNUMBER(SEARCH(B3,Master!$J$2:$J$2000))*(Master!$V$2:$V$2000<>"Done")*(Master!$V$2:$V$2000<>"Cancelled")*Master!$T$2:$T$2000) -> 0 | M3: =IF(OR(H3="",H3=0),"",L3/H3) -> 0 | N3: =COUNTIF(Catalog!$F$2:$F$200,B3) -> 1
A4: S03 | B4: Venya | C4: Lovenya, Ve, Venya | D4: Finance | F4: Intern (runs an intern project) | H4: 1 | I4: =COUNTIFS(Master!$I$2:$I$2000,B4,Master!$V$2:$V$2000,"<>Done",Master!$V$2:$V$2000,"<>Cancelled",Master!$C$2:$C$2000,"<>") -> 0 | J4: =SUMPRODUCT(ISNUMBER(SEARCH(B4,Master!$J$2:$J$2000))*(Master!$V$2:$V$2000<>"Done")*(Master!$V$2:$V$2000<>"Cancelled")*(Master!$C$2:$C$2000<>"")) -> 0 | K4: =COUNTIFS(Master!$H$2:$H$2000,B4,Master!$V$2:$V$2000,"<>Done",Master!$V$2:$V$2000,"<>Cancelled",Master!$P$2:$P$2000,"<"&TODAY()) -> 0 | L4: =SUMPRODUCT((Master!$I$2:$I$2000=B4)*(Master!$V$2:$V$2000<>"Done")*(Master!$V$2:$V$2000<>"Cancelled")*Master!$T$2:$T$2000)+Config!$B$5*SUMPRODUCT(ISNUMBER(SEARCH(B4,Master!$J$2:$J$2000))*(Master!$V$2:$V$2000<>"Done")*(Master!$V$2:$V$2000<>"Cancelled")*Master!$T$2:$T$2000) -> 0 | M4: =IF(OR(H4="",H4=0),"",L4/H4) -> 0 | N4: =COUNTIF(Catalog!$F$2:$F$200,B4) -> 1
A5: S04 | B5: Gwen | C5: Gwen | D5: Policy and Risk | H5: 1 | I5: =COUNTIFS(Master!$I$2:$I$2000,B5,Master!$V$2:$V$2000,"<>Done",Master!$V$2:$V$2000,"<>Cancelled",Master!$C$2:$C$2000,"<>") -> 0 | J5: =SUMPRODUCT(ISNUMBER(SEARCH(B5,Master!$J$2:$J$2000))*(Master!$V$2:$V$2000<>"Done")*(Master!$V$2:$V$2000<>"Cancelled")*(Master!$C$2:$C$2000<>"")) -> 0 | K5: =COUNTIFS(Master!$H$2:$H$2000,B5,Master!$V$2:$V$2000,"<>Done",Master!$V$2:$V$2000,"<>Cancelled",Master!$P$2:$P$2000,"<"&TODAY()) -> 0 | L5: =SUMPRODUCT((Master!$I$2:$I$2000=B5)*(Master!$V$2:$V$2000<>"Done")*(Master!$V$2:$V$2000<>"Cancelled")*Master!$T$2:$T$2000)+Config!$B$5*SUMPRODUCT(ISNUMBER(SEARCH(B5,Master!$J$2:$J$2000))*(Master!$V$2:$V$2000<>"Done")*(Master!$V$2:$V$2000<>"Cancelled")*Master!$T$2:$T$2000) -> 0 | M5: =IF(OR(H5="",H5=0),"",L5/H5) -> 0 | N5: =COUNTIF(Catalog!$F$2:$F$200,B5) -> 5
A6: S05 | B6: Selina | C6: Sel, Selina, Seline | D6: Compliance | F6: Intern (runs an intern project) | H6: 1 | I6: =COUNTIFS(Master!$I$2:$I$2000,B6,Master!$V$2:$V$2000,"<>Done",Master!$V$2:$V$2000,"<>Cancelled",Master!$C$2:$C$2000,"<>") -> 0 | J6: =SUMPRODUCT(ISNUMBER(SEARCH(B6,Master!$J$2:$J$2000))*(Master!$V$2:$V$2000<>"Done")*(Master!$V$2:$V$2000<>"Cancelled")*(Master!$C$2:$C$2000<>"")) -> 0 | K6: =COUNTIFS(Master!$H$2:$H$2000,B6,Master!$V$2:$V$2000,"<>Done",Master!$V$2:$V$2000,"<>Cancelled",Master!$P$2:$P$2000,"<"&TODAY()) -> 0 | L6: =SUMPRODUCT((Master!$I$2:$I$2000=B6)*(Master!$V$2:$V$2000<>"Done")*(Master!$V$2:$V$2000<>"Cancelled")*Master!$T$2:$T$2000)+Config!$B$5*SUMPRODUCT(ISNUMBER(SEARCH(B6,Master!$J$2:$J$2000))*(Master!$V$2:$V$2000<>"Done")*(Master!$V$2:$V$2000<>"Cancelled")*Master!$T$2:$T$2000) -> 0 | M6: =IF(OR(H6="",H6=0),"",L6/H6) -> 0 | N6: =COUNTIF(Catalog!$F$2:$F$200,B6) -> 0
A7: S06 | B7: Ivy | C7: Ivy | D7: HR | F7: Intern (runs an intern project) | H7: 1 | I7: =COUNTIFS(Master!$I$2:$I$2000,B7,Master!$V$2:$V$2000,"<>Done",Master!$V$2:$V$2000,"<>Cancelled",Master!$C$2:$C$2000,"<>") -> 0 | J7: =SUMPRODUCT(ISNUMBER(SEARCH(B7,Master!$J$2:$J$2000))*(Master!$V$2:$V$2000<>"Done")*(Master!$V$2:$V$2000<>"Cancelled")*(Master!$C$2:$C$2000<>"")) -> 0 | K7: =COUNTIFS(Master!$H$2:$H$2000,B7,Master!$V$2:$V$2000,"<>Done",Master!$V$2:$V$2000,"<>Cancelled",Master!$P$2:$P$2000,"<"&TODAY()) -> 0 | L7: =SUMPRODUCT((Master!$I$2:$I$2000=B7)*(Master!$V$2:$V$2000<>"Done")*(Master!$V$2:$V$2000<>"Cancelled")*Master!$T$2:$T$2000)+Config!$B$5*SUMPRODUCT(ISNUMBER(SEARCH(B7,Master!$J$2:$J$2000))*(Master!$V$2:$V$2000<>"Done")*(Master!$V$2:$V$2000<>"Cancelled")*Master!$T$2:$T$2000) -> 0 | M7: =IF(OR(H7="",H7=0),"",L7/H7) -> 0 | N7: =COUNTIF(Catalog!$F$2:$F$200,B7) -> 4
A8: S07 | B8: Leila | C8: Kak Leila, Leila, kak Leila | D8: Finance | H8: 1 | I8: =COUNTIFS(Master!$I$2:$I$2000,B8,Master!$V$2:$V$2000,"<>Done",Master!$V$2:$V$2000,"<>Cancelled",Master!$C$2:$C$2000,"<>") -> 0 | J8: =SUMPRODUCT(ISNUMBER(SEARCH(B8,Master!$J$2:$J$2000))*(Master!$V$2:$V$2000<>"Done")*(Master!$V$2:$V$2000<>"Cancelled")*(Master!$C$2:$C$2000<>"")) -> 0 | K8: =COUNTIFS(Master!$H$2:$H$2000,B8,Master!$V$2:$V$2000,"<>Done",Master!$V$2:$V$2000,"<>Cancelled",Master!$P$2:$P$2000,"<"&TODAY()) -> 0 | L8: =SUMPRODUCT((Master!$I$2:$I$2000=B8)*(Master!$V$2:$V$2000<>"Done")*(Master!$V$2:$V$2000<>"Cancelled")*Master!$T$2:$T$2000)+Config!$B$5*SUMPRODUCT(ISNUMBER(SEARCH(B8,Master!$J$2:$J$2000))*(Master!$V$2:$V$2000<>"Done")*(Master!$V$2:$V$2000<>"Cancelled")*Master!$T$2:$T$2000) -> 0 | M8: =IF(OR(H8="",H8=0),"",L8/H8) -> 0 | N8: =COUNTIF(Catalog!$F$2:$F$200,B8) -> 8
A9: S08 | B9: Cynthia | C9: Cynthia | D9: Audit | F9: Intern (runs an intern project) | H9: 1 | I9: =COUNTIFS(Master!$I$2:$I$2000,B9,Master!$V$2:$V$2000,"<>Done",Master!$V$2:$V$2000,"<>Cancelled",Master!$C$2:$C$2000,"<>") -> 0 | J9: =SUMPRODUCT(ISNUMBER(SEARCH(B9,Master!$J$2:$J$2000))*(Master!$V$2:$V$2000<>"Done")*(Master!$V$2:$V$2000<>"Cancelled")*(Master!$C$2:$C$2000<>"")) -> 0 | K9: =COUNTIFS(Master!$H$2:$H$2000,B9,Master!$V$2:$V$2000,"<>Done",Master!$V$2:$V$2000,"<>Cancelled",Master!$P$2:$P$2000,"<"&TODAY()) -> 0 | L9: =SUMPRODUCT((Master!$I$2:$I$2000=B9)*(Master!$V$2:$V$2000<>"Done")*(Master!$V$2:$V$2000<>"Cancelled")*Master!$T$2:$T$2000)+Config!$B$5*SUMPRODUCT(ISNUMBER(SEARCH(B9,Master!$J$2:$J$2000))*(Master!$V$2:$V$2000<>"Done")*(Master!$V$2:$V$2000<>"Cancelled")*Master!$T$2:$T$2000) -> 0 | M9: =IF(OR(H9="",H9=0),"",L9/H9) -> 0 | N9: =COUNTIF(Catalog!$F$2:$F$200,B9) -> 1
A10: S09 | B10: Natalie | C10: Natalie | D10: Policy and Risk | H10: 1 | I10: =COUNTIFS(Master!$I$2:$I$2000,B10,Master!$V$2:$V$2000,"<>Done",Master!$V$2:$V$2000,"<>Cancelled",Master!$C$2:$C$2000,"<>") -> 0 | J10: =SUMPRODUCT(ISNUMBER(SEARCH(B10,Master!$J$2:$J$2000))*(Master!$V$2:$V$2000<>"Done")*(Master!$V$2:$V$2000<>"Cancelled")*(Master!$C$2:$C$2000<>"")) -> 0 | K10: =COUNTIFS(Master!$H$2:$H$2000,B10,Master!$V$2:$V$2000,"<>Done",Master!$V$2:$V$2000,"<>Cancelled",Master!$P$2:$P$2000,"<"&TODAY()) -> 0 | L10: =SUMPRODUCT((Master!$I$2:$I$2000=B10)*(Master!$V$2:$V$2000<>"Done")*(Master!$V$2:$V$2000<>"Cancelled")*Master!$T$2:$T$2000)+Config!$B$5*SUMPRODUCT(ISNUMBER(SEARCH(B10,Master!$J$2:$J$2000))*(Master!$V$2:$V$2000<>"Done")*(Master!$V$2:$V$2000<>"Cancelled")*Master!$T$2:$T$2000) -> 0 | M10: =IF(OR(H10="",H10=0),"",L10/H10) -> 0 | N10: =COUNTIF(Catalog!$F$2:$F$200,B10) -> 2
A11: S10 | B11: Adeline | C11: Adel, Adeline | D11: Audit | H11: 1 | I11: =COUNTIFS(Master!$I$2:$I$2000,B11,Master!$V$2:$V$2000,"<>Done",Master!$V$2:$V$2000,"<>Cancelled",Master!$C$2:$C$2000,"<>") -> 0 | J11: =SUMPRODUCT(ISNUMBER(SEARCH(B11,Master!$J$2:$J$2000))*(Master!$V$2:$V$2000<>"Done")*(Master!$V$2:$V$2000<>"Cancelled")*(Master!$C$2:$C$2000<>"")) -> 0 | K11: =COUNTIFS(Master!$H$2:$H$2000,B11,Master!$V$2:$V$2000,"<>Done",Master!$V$2:$V$2000,"<>Cancelled",Master!$P$2:$P$2000,"<"&TODAY()) -> 0 | L11: =SUMPRODUCT((Master!$I$2:$I$2000=B11)*(Master!$V$2:$V$2000<>"Done")*(Master!$V$2:$V$2000<>"Cancelled")*Master!$T$2:$T$2000)+Config!$B$5*SUMPRODUCT(ISNUMBER(SEARCH(B11,Master!$J$2:$J$2000))*(Master!$V$2:$V$2000<>"Done")*(Master!$V$2:$V$2000<>"Cancelled")*Master!$T$2:$T$2000) -> 0 | M11: =IF(OR(H11="",H11=0),"",L11/H11) -> 0 | N11: =COUNTIF(Catalog!$F$2:$F$200,B11) -> 1
A12: S11 | B12: Dicki | C12: Dicki, Pak Dicki | D12: Compliance | F12: Manager | I12: =COUNTIFS(Master!$I$2:$I$2000,B12,Master!$V$2:$V$2000,"<>Done",Master!$V$2:$V$2000,"<>Cancelled",Master!$C$2:$C$2000,"<>") -> 0 | J12: =SUMPRODUCT(ISNUMBER(SEARCH(B12,Master!$J$2:$J$2000))*(Master!$V$2:$V$2000<>"Done")*(Master!$V$2:$V$2000<>"Cancelled")*(Master!$C$2:$C$2000<>"")) -> 0 | K12: =COUNTIFS(Master!$H$2:$H$2000,B12,Master!$V$2:$V$2000,"<>Done",Master!$V$2:$V$2000,"<>Cancelled",Master!$P$2:$P$2000,"<"&TODAY()) -> 0 | L12: =SUMPRODUCT((Master!$I$2:$I$2000=B12)*(Master!$V$2:$V$2000<>"Done")*(Master!$V$2:$V$2000<>"Cancelled")*Master!$T$2:$T$2000)+Config!$B$5*SUMPRODUCT(ISNUMBER(SEARCH(B12,Master!$J$2:$J$2000))*(Master!$V$2:$V$2000<>"Done")*(Master!$V$2:$V$2000<>"Cancelled")*Master!$T$2:$T$2000) -> 0 | M12: =IF(OR(H12="",H12=0),"",L12/H12) | N12: =COUNTIF(Catalog!$F$2:$F$200,B12) -> 0
A13: S12 | B13: Hillary | C13: Hil, Hillary | D13: Compliance | F13: Intern (intern presentation) | H13: 1 | I13: =COUNTIFS(Master!$I$2:$I$2000,B13,Master!$V$2:$V$2000,"<>Done",Master!$V$2:$V$2000,"<>Cancelled",Master!$C$2:$C$2000,"<>") -> 0 | J13: =SUMPRODUCT(ISNUMBER(SEARCH(B13,Master!$J$2:$J$2000))*(Master!$V$2:$V$2000<>"Done")*(Master!$V$2:$V$2000<>"Cancelled")*(Master!$C$2:$C$2000<>"")) -> 0 | K13: =COUNTIFS(Master!$H$2:$H$2000,B13,Master!$V$2:$V$2000,"<>Done",Master!$V$2:$V$2000,"<>Cancelled",Master!$P$2:$P$2000,"<"&TODAY()) -> 0 | L13: =SUMPRODUCT((Master!$I$2:$I$2000=B13)*(Master!$V$2:$V$2000<>"Done")*(Master!$V$2:$V$2000<>"Cancelled")*Master!$T$2:$T$2000)+Config!$B$5*SUMPRODUCT(ISNUMBER(SEARCH(B13,Master!$J$2:$J$2000))*(Master!$V$2:$V$2000<>"Done")*(Master!$V$2:$V$2000<>"Cancelled")*Master!$T$2:$T$2000) -> 0 | M13: =IF(OR(H13="",H13=0),"",L13/H13) -> 0 | N13: =COUNTIF(Catalog!$F$2:$F$200,B13) -> 0
A14: S13 | B14: Abia | C14: Abia | D14: Policy and Risk | H14: 1 | I14: =COUNTIFS(Master!$I$2:$I$2000,B14,Master!$V$2:$V$2000,"<>Done",Master!$V$2:$V$2000,"<>Cancelled",Master!$C$2:$C$2000,"<>") -> 0 | J14: =SUMPRODUCT(ISNUMBER(SEARCH(B14,Master!$J$2:$J$2000))*(Master!$V$2:$V$2000<>"Done")*(Master!$V$2:$V$2000<>"Cancelled")*(Master!$C$2:$C$2000<>"")) -> 0 | K14: =COUNTIFS(Master!$H$2:$H$2000,B14,Master!$V$2:$V$2000,"<>Done",Master!$V$2:$V$2000,"<>Cancelled",Master!$P$2:$P$2000,"<"&TODAY()) -> 0 | L14: =SUMPRODUCT((Master!$I$2:$I$2000=B14)*(Master!$V$2:$V$2000<>"Done")*(Master!$V$2:$V$2000<>"Cancelled")*Master!$T$2:$T$2000)+Config!$B$5*SUMPRODUCT(ISNUMBER(SEARCH(B14,Master!$J$2:$J$2000))*(Master!$V$2:$V$2000<>"Done")*(Master!$V$2:$V$2000<>"Cancelled")*Master!$T$2:$T$2000) -> 0 | M14: =IF(OR(H14="",H14=0),"",L14/H14) -> 0 | N14: =COUNTIF(Catalog!$F$2:$F$200,B14) -> 0
A15: S14 | B15: Albert | C15: Albert | D15: Finance | H15: 1 | I15: =COUNTIFS(Master!$I$2:$I$2000,B15,Master!$V$2:$V$2000,"<>Done",Master!$V$2:$V$2000,"<>Cancelled",Master!$C$2:$C$2000,"<>") -> 0 | J15: =SUMPRODUCT(ISNUMBER(SEARCH(B15,Master!$J$2:$J$2000))*(Master!$V$2:$V$2000<>"Done")*(Master!$V$2:$V$2000<>"Cancelled")*(Master!$C$2:$C$2000<>"")) -> 0 | K15: =COUNTIFS(Master!$H$2:$H$2000,B15,Master!$V$2:$V$2000,"<>Done",Master!$V$2:$V$2000,"<>Cancelled",Master!$P$2:$P$2000,"<"&TODAY()) -> 0 | L15: =SUMPRODUCT((Master!$I$2:$I$2000=B15)*(Master!$V$2:$V$2000<>"Done")*(Master!$V$2:$V$2000<>"Cancelled")*Master!$T$2:$T$2000)+Config!$B$5*SUMPRODUCT(ISNUMBER(SEARCH(B15,Master!$J$2:$J$2000))*(Master!$V$2:$V$2000<>"Done")*(Master!$V$2:$V$2000<>"Cancelled")*Master!$T$2:$T$2000) -> 0 | M15: =IF(OR(H15="",H15=0),"",L15/H15) -> 0 | N15: =COUNTIF(Catalog!$F$2:$F$200,B15) -> 0
A16: S15 | B16: Ken | C16: Ken | D16: Compliance | H16: 1 | I16: =COUNTIFS(Master!$I$2:$I$2000,B16,Master!$V$2:$V$2000,"<>Done",Master!$V$2:$V$2000,"<>Cancelled",Master!$C$2:$C$2000,"<>") -> 0 | J16: =SUMPRODUCT(ISNUMBER(SEARCH(B16,Master!$J$2:$J$2000))*(Master!$V$2:$V$2000<>"Done")*(Master!$V$2:$V$2000<>"Cancelled")*(Master!$C$2:$C$2000<>"")) -> 0 | K16: =COUNTIFS(Master!$H$2:$H$2000,B16,Master!$V$2:$V$2000,"<>Done",Master!$V$2:$V$2000,"<>Cancelled",Master!$P$2:$P$2000,"<"&TODAY()) -> 0 | L16: =SUMPRODUCT((Master!$I$2:$I$2000=B16)*(Master!$V$2:$V$2000<>"Done")*(Master!$V$2:$V$2000<>"Cancelled")*Master!$T$2:$T$2000)+Config!$B$5*SUMPRODUCT(ISNUMBER(SEARCH(B16,Master!$J$2:$J$2000))*(Master!$V$2:$V$2000<>"Done")*(Master!$V$2:$V$2000<>"Cancelled")*Master!$T$2:$T$2000) -> 0 | M16: =IF(OR(H16="",H16=0),"",L16/H16) -> 0 | N16: =COUNTIF(Catalog!$F$2:$F$200,B16) -> 0
A17: S16 | B17: Cindy | C17: Cindy | D17: HR | H17: 1 | I17: =COUNTIFS(Master!$I$2:$I$2000,B17,Master!$V$2:$V$2000,"<>Done",Master!$V$2:$V$2000,"<>Cancelled",Master!$C$2:$C$2000,"<>") -> 0 | J17: =SUMPRODUCT(ISNUMBER(SEARCH(B17,Master!$J$2:$J$2000))*(Master!$V$2:$V$2000<>"Done")*(Master!$V$2:$V$2000<>"Cancelled")*(Master!$C$2:$C$2000<>"")) -> 0 | K17: =COUNTIFS(Master!$H$2:$H$2000,B17,Master!$V$2:$V$2000,"<>Done",Master!$V$2:$V$2000,"<>Cancelled",Master!$P$2:$P$2000,"<"&TODAY()) -> 0 | L17: =SUMPRODUCT((Master!$I$2:$I$2000=B17)*(Master!$V$2:$V$2000<>"Done")*(Master!$V$2:$V$2000<>"Cancelled")*Master!$T$2:$T$2000)+Config!$B$5*SUMPRODUCT(ISNUMBER(SEARCH(B17,Master!$J$2:$J$2000))*(Master!$V$2:$V$2000<>"Done")*(Master!$V$2:$V$2000<>"Cancelled")*Master!$T$2:$T$2000) -> 0 | M17: =IF(OR(H17="",H17=0),"",L17/H17) -> 0 | N17: =COUNTIF(Catalog!$F$2:$F$200,B17) -> 0
A18: S17 | B18: Ben | C18: Pak Ben | H18: 1 | I18: =COUNTIFS(Master!$I$2:$I$2000,B18,Master!$V$2:$V$2000,"<>Done",Master!$V$2:$V$2000,"<>Cancelled",Master!$C$2:$C$2000,"<>") -> 0 | J18: =SUMPRODUCT(ISNUMBER(SEARCH(B18,Master!$J$2:$J$2000))*(Master!$V$2:$V$2000<>"Done")*(Master!$V$2:$V$2000<>"Cancelled")*(Master!$C$2:$C$2000<>"")) -> 0 | K18: =COUNTIFS(Master!$H$2:$H$2000,B18,Master!$V$2:$V$2000,"<>Done",Master!$V$2:$V$2000,"<>Cancelled",Master!$P$2:$P$2000,"<"&TODAY()) -> 0 | L18: =SUMPRODUCT((Master!$I$2:$I$2000=B18)*(Master!$V$2:$V$2000<>"Done")*(Master!$V$2:$V$2000<>"Cancelled")*Master!$T$2:$T$2000)+Config!$B$5*SUMPRODUCT(ISNUMBER(SEARCH(B18,Master!$J$2:$J$2000))*(Master!$V$2:$V$2000<>"Done")*(Master!$V$2:$V$2000<>"Cancelled")*Master!$T$2:$T$2000) -> 0 | M18: =IF(OR(H18="",H18=0),"",L18/H18) -> 0 | N18: =COUNTIF(Catalog!$F$2:$F$200,B18) -> 0
A19: S18 | B19: Flynn | C19: Flynn | F19: Intern (intern presentation) | H19: 1 | I19: =COUNTIFS(Master!$I$2:$I$2000,B19,Master!$V$2:$V$2000,"<>Done",Master!$V$2:$V$2000,"<>Cancelled",Master!$C$2:$C$2000,"<>") -> 0 | J19: =SUMPRODUCT(ISNUMBER(SEARCH(B19,Master!$J$2:$J$2000))*(Master!$V$2:$V$2000<>"Done")*(Master!$V$2:$V$2000<>"Cancelled")*(Master!$C$2:$C$2000<>"")) -> 0 | K19: =COUNTIFS(Master!$H$2:$H$2000,B19,Master!$V$2:$V$2000,"<>Done",Master!$V$2:$V$2000,"<>Cancelled",Master!$P$2:$P$2000,"<"&TODAY()) -> 0 | L19: =SUMPRODUCT((Master!$I$2:$I$2000=B19)*(Master!$V$2:$V$2000<>"Done")*(Master!$V$2:$V$2000<>"Cancelled")*Master!$T$2:$T$2000)+Config!$B$5*SUMPRODUCT(ISNUMBER(SEARCH(B19,Master!$J$2:$J$2000))*(Master!$V$2:$V$2000<>"Done")*(Master!$V$2:$V$2000<>"Cancelled")*Master!$T$2:$T$2000) -> 0 | M19: =IF(OR(H19="",H19=0),"",L19/H19) -> 0 | N19: =COUNTIF(Catalog!$F$2:$F$200,B19) -> 0

Sheet Catalog
A1: Catalog ID | B1: Report type | C1: Division | D1: Regulator / Institution | E1: Recurrence | F1: Default owner | G1: Backup | H1: Typical due day | I1: Due months seen (2026) | J1: Usually sent to | K1: Times logged | L1: Notes | M1: Confirmed by manager? | N1: Match keywords
A2: RM-MONTHLY | B2: Monthly RAS & Risk Profile letters (internal) | C2: Policy and Risk | D2: Internal | E2: Monthly | F2: Stesya | H2: 22 | I2: Jul, Aug, Sep, Oct | J2: waiting for approval pak Dicki | K2: =COUNTIF(Master!$D$2:$D$2000,A2) -> 0 | L2: Prepared internally after month-end, then sent to BRI Pusat | N2: ras bulan, profil risiko bulan, laporan ras bulan, surat laporan ras, surat laporan profil risiko, monthly ras, laporan ras, laporan profil risiko, ras & profil risiko
A3: RM-PROFIL-Q | B3: Risk Profile working paper (to BRI Pusat) | C3: Policy and Risk | D3: BRI Pusat | E3: Quarterly | F3: Stesya | G3: Natalie | H3: 23 | I3: Jan, Jul, Oct | J3: ke email bimo SBM | K3: =COUNTIF(Master!$D$2:$D$2000,A3) -> 0 | N3: profil risiko, kertas kerja profil risiko, risk profile
A4: RM-RAS-Q | B4: RAS quarterly / annual statement | C4: Policy and Risk | D4: BRI Pusat | E4: Quarterly | F4: Stesya | G4: Natalie | H4: 16 | I4: Jul, Oct | J4: Email: rafa.nismara.dahayu@brilian.bri.co.id | K4: =COUNTIF(Master!$D$2:$D$2000,A4) -> 0 | L4: Annual RAS statement in January | N4: ras triwulan, risk appetite, ras q, risk appettite, risk appetite statement, ras q1, ras q2, ras q3, ras q4, penyesuaian parameter ras
A5: RM-LIMIT | B5: Risk limits & RAS parameters for next year | C5: Policy and Risk | D5: BRI Pusat | E5: Annual | F5: Stesya | H5: 22 | I5: Sep | J5: Email: a.fatmawati@brilian.bri.co.id | K5: =COUNTIF(Master!$D$2:$D$2000,A5) -> 0 | N5: limit risiko, parameter ras
A6: RM-STRESS | B6: Stress test | C6: Policy and Risk | D6: BRI Pusat | E6: Quarterly | F6: Stesya | H6: 16 | I6: Jul, Aug, Oct | J6: Baru send ke WA Mba Restu | K6: =COUNTIF(Master!$D$2:$D$2000,A6) -> 0 | L6: Also an HKD version | N6: stress test
A7: FIN-ATMR | B7: ATMR (risk-weighted assets) | C7: Finance | D7: BRI Pusat | E7: Monthly | F7: Leila | H7: 15 | I7: Jul, Aug, Oct | J7: Email: ayu.putu.alika.pramesvari@brilian.bri.co.id | K7: =COUNTIF(Master!$D$2:$D$2000,A7) -> 1 | L7: Confirm: monthly or quarterly | N7: atmr
A8: FIN-KPMM | B8: KPMM / capital adequacy | C8: Finance | D8: BRI Pusat | E8: Quarterly | F8: Leila | H8: 20 | I8: Jul, Oct | J8: Email: bagianlpk@corp.bri.co.id | K8: =COUNTIF(Master!$D$2:$D$2000,A8) -> 0 | N8: kpmm, permodalan
A9: FIN-CAPEX | B9: CAPEX reporting | C9: Finance | D9: BRI Pusat | E9: Quarterly | F9: Leila | H9: 16 | I9: Jul, Aug, Sep | J9: email: bri.sbm@bri.co.id | K9: =COUNTIF(Master!$D$2:$D$2000,A9) -> 0 | N9: capex
A10: FIN-PROJ | B10: RKAP, budget & financial projections | C10: Finance | D10: BRI Pusat | E10: Annual | F10: Leila | G10: Venya | H10: 23 | I10: Jul, Sep, Oct | J10: acc&fin group & sbm | K10: =COUNTIF(Master!$D$2:$D$2000,A10) -> 0 | L10: Prognosa laba may be monthly | N10: rkap, proyeksi, prognosa
A11: FIN-GROUPCONF | B11: Group financial confirmations (FRP, ICOFR, employee benefits, CBCR) | C11: Finance | D11: BRI Pusat | E11: Quarterly | F11: Leila | G11: Stesya | H11: 13 | I11: Jul, Aug, Oct | J11: WA ke Pak Haris SBM | K11: =COUNTIF(Master!$D$2:$D$2000,A11) -> 0 | L11: Confirm frequency | N11: frp, icofr, imbalan kerja, cbcr, intragroup
A12: FIN-AKAM | B12: AKAM data pack (bank statement, loan portfolio, POS, LexisNexis) | C12: Finance | D12: AKAM | E12: Quarterly | F12: Leila | G12: Albert | H12: 15 | I12: Jul | J12: pak dicki | K12: =COUNTIF(Master!$D$2:$D$2000,A12) -> 0 | L12: Confirm frequency | N12: akam, loan portfolio, lexis nexis, bank statement, loan portofolio, transaction pos
A13: CMP-CALK | B13: CALK, Longform & Representation Letter | C13: Compliance | D13: BRI Pusat | E13: Quarterly | F13: Gwen | G13: Natalie | H13: 17 | I13: Jan, Jul, Oct | J13: SBM Group | K13: =COUNTIF(Master!$D$2:$D$2000,A13) -> 0 | N13: calk, longform, representation letter
A14: CMP-TATAKELOLA | B14: Corporate governance report (Laporan Tata Kelola) | C14: Compliance | D14: BRI Pusat | E14: Quarterly | F14: Gwen | G14: Cia | H14: 29 | I14: Jul, Aug, Oct | J14: Mas Faiq | K14: =COUNTIF(Master!$D$2:$D$2000,A14) -> 0 | N14: laporan tata kelola, tata kelola perusahaan
A15: CMP-SAGCG | B15: GCG self-assessment | C15: Policy and Risk | D15: BRI Pusat | E15: Semester | F15: Stesya | G15: Ivy | H15: 15 | I15: Jul | J15: Email: kepatuhan@corp.bri.co.id | K15: =COUNTIF(Master!$D$2:$D$2000,A15) -> 0 | N15: sa gcg, self assessment gcg, penilaian gcg
A16: CMP-SATKT | B16: Integrated governance self-assessment (SA TKT) | C16: Policy and Risk | D16: BRI Pusat | E16: Semester | F16: Stesya | H16: 18 | I16: Jan, Jul | J16: Email: rafa.nismara.dahayu@brilian.bri.co.id | K16: =COUNTIF(Master!$D$2:$D$2000,A16) -> 0 | N16: sa tkt, tata kelola terintegrasi
A17: CMP-KTKT | B17: Integrated Governance Committee (KTKT) | C17: Compliance | D17: BRI Pusat | E17: Quarterly | F17: Gwen | H17: 23 | I17: Jul, Sep | J17: pak dicki | K17: =COUNTIF(Master!$D$2:$D$2000,A17) -> 0 | N17: ktkt, komite tata kelola terintegrasi
A18: CMP-MR | B18: Risk management implementation reports (credit & operational) | C18: Compliance | D18: BRI Pusat | E18: Semester | F18: Venya | G18: Natalie | H18: 24 | I18: Feb, Jul | J18: to a.fatmawati@brilian.bri.co.id | K18: =COUNTIF(Master!$D$2:$D$2000,A18) -> 0 | N18: manajemen risiko kredit, manajemen risiko operasional, laporan mr, risiko operasional, manajemen risiko
A19: CMP-HEALTH | B19: Company health assessment (Tingkat Kesehatan, TKB) | C19: Compliance | D19: BRI Pusat | E19: Semester | F19: Stesya | G19: Venya | H19: 31 | I19: Jul | J19: to a.fatmawati@brilian.bri.co.id | K19: =COUNTIF(Master!$D$2:$D$2000,A19) -> 0 | N19: tingkat kesehatan, kesehatan perusahaan, tkb, tkb kertas kerja
A20: CMP-RELATED | B20: Related parties report (Pihak Terkait) | C20: Compliance | D20: BRI Pusat | E20: Semester | F20: Leila | G20: Stesya | H20: 23 | I20: Jan, Jul | J20: upload di onedrive | K20: =COUNTIF(Master!$D$2:$D$2000,A20) -> 0 | N20: pihak terkait
A21: CMP-OWNERSHIP | B21: Shareholding & conglomerate member data | C21: Compliance | D21: BRI Pusat | E21: Semester | F21: Leila | G21: Natalie | H21: 22 | I21: Jul, Aug | J21: pak dicki | K21: =COUNTIF(Master!$D$2:$D$2000,A21) -> 0 | N21: kepemilikan saham, anggota konglomerasi
A22: CMP-PUBLIKASI | B22: Risk & capital publication list | C22: Policy and Risk | D22: BRI Pusat | E22: Quarterly | F22: Stesya | G22: Natalie | H22: 23 | I22: Jul | J22: Email: ayu.putu.alika.pramesvari@brilian.bri.co.id, rini.astuti@corp.bri.co.id | K22: =COUNTIF(Master!$D$2:$D$2000,A22) -> 0 | N22: laporan publikasi, publikasi eksposur
A23: CMP-KKDATA | B23: BRI conglomerate data updates (negative news, complaints, core debtors, credit by segment) | C23: Compliance | D23: BRI Pusat | E23: Semester | F23: Stesya | H23: 26 | I23: Aug | J23: Email Mba Rafa | K23: =COUNTIF(Master!$D$2:$D$2000,A23) -> 0 | N23: pemberitaan negatif, pengaduan nasabah, debitur inti, kredit per segmen
A24: CMP-SINERGI | B24: BRI synergy realisation | C24: Compliance | D24: BRI Pusat | E24: Monthly | F24: Stesya | H24: 13 | I24: Oct | J24: Sent to Email SBM | K24: =COUNTIF(Master!$D$2:$D$2000,A24) -> 0 | L24: Confirm frequency | N24: sinergi
A25: CMP-ESG | B25: Emissions working paper (Scope 1 & 2) | C25: Compliance | D25: BRI Pusat | E25: Semester | F25: Cia | H25: 31 | I25: Jul | K25: =COUNTIF(Master!$D$2:$D$2000,A25) -> 0 | N25: emisi, scope 1, scope 2
A26: CMP-FORUM | B26: Subsidiaries Forum, Genba & RMCT materials | C26: Compliance | D26: BRI Pusat | E26: Quarterly | F26: Stesya | G26: Ken | H26: 20 | I26: Aug, Oct | J26: Lewat Pak Dicki | K26: =COUNTIF(Master!$D$2:$D$2000,A26) -> 0 | N26: subsidiaries forum, genba, rmct
A27: CMP-AML | B27: AML/CFT (APU PPT) evaluation | C27: Compliance | D27: BRI Pusat | E27: Annual | J27: submitted to meisya by wa | K27: =COUNTIF(Master!$D$2:$D$2000,A27) -> 0 | N27: apu ppt, apu-ppt, aml
A28: REG-CR-QR | B28: Companies Registry quarterly return (complaints & debt collection) | C28: Compliance | D28: Companies Registry | E28: Quarterly | F28: Gwen | G28: Stesya | H28: 15 | I28: Feb, Jul, Oct | J28: mlu@cr.gov.hk | K28: =COUNTIF(Master!$D$2:$D$2000,A28) -> 0 | L28: Due 15th of the month after quarter-end (check) | N28: complaint handling, debt collector, quarterly return
A29: REG-CR-PL | B29: Companies Registry personal loan report | C29: Compliance | D29: Companies Registry | E29: Quarterly | F29: Ivy | H29: 15 | I29: Jan | J29: by email | K29: =COUNTIF(Master!$D$2:$D$2000,A29) -> 0 | N29: personal loan
A30: REG-ML | B30: Money lender licence renewal & forms | C30: Compliance | D30: Companies Registry | E30: Annual | F30: Natalie | K30: =COUNTIF(Master!$D$2:$D$2000,A30) -> 0 | N30: money lender
A31: REG-MSO | B31: MSO licence renewal & requests | C31: Compliance | D31: Companies Registry | E31: Annual | F31: Stesya | G31: Gwen | H31: 13 | I31: Aug, Sep, Oct | J31: MSO Office | K31: =COUNTIF(Master!$D$2:$D$2000,A31) -> 0 | L31: Includes ad hoc officer requests | N31: mso
A32: REG-DBS | B32: DBS due diligence | C32: Compliance | D32: DBS | E32: Annual | F32: Natalie | K32: =COUNTIF(Master!$D$2:$D$2000,A32) -> 0 | N32: dbs
A33: PR-RMI | B33: Risk Maturity Index (RMI) | C33: Policy and Risk | D33: BRI Pusat | E33: Annual | F33: Gwen | G33: Stesya | H33: 26 | I33: Jan, Dec | K33: =COUNTIF(Master!$D$2:$D$2000,A33) -> 0 | N33: rmi, risk maturity
A34: PR-MATURITY | B34: Compliance & governance maturity working papers | C34: Policy and Risk | D34: BRI Pusat | E34: Annual | F34: Ivy | G34: Natalie | K34: =COUNTIF(Master!$D$2:$D$2000,A34) -> 0 | N34: maturitas kepatuhan, maturitas tata kelola
A35: AUD-WBS | B35: Whistleblowing (WBS) report | C35: Audit | D35: Internal | E35: Semester | F35: Cynthia | H35: 11 | I35: Sep | J35: Adel | K35: =COUNTIF(Master!$D$2:$D$2000,A35) -> 0 | N35: wbs, whistleblowing
A36: AUD-REQ | B36: Internal audit requests (SKAI, IA maturity, audit confirmations) | C36: Audit | D36: BRI Pusat | E36: Ad hoc | F36: Adeline | G36: Stesya | H36: 22 | I36: Oct | J36: GRC | K36: =COUNTIF(Master!$D$2:$D$2000,A36) -> 0 | N36: skai, internal audit, audit, ia maturitas, sdm profile ia, maturitas fungsi internal audit
A37: HR-DATA | B37: Employee data & talent mapping | C37: HR | D37: BRI Pusat | E37: Quarterly | F37: Ivy | G37: Cindy | H37: 15 | I37: Jul, Oct | J37: bri.sbm@bri.co.id | K37: =COUNTIF(Master!$D$2:$D$2000,A37) -> 0 | L37: Confirm frequency | N37: data pegawai, data karyawan, talent, outsource
A38: HR-POLICY | B38: HR policies & HC assessments | C38: HR | D38: Internal | E38: Ad hoc | F38: Ivy | G38: Dicki | H38: 24 | I38: Aug | J38: hirza.sitaningtyas@bri.co.id | K38: =COUNTIF(Master!$D$2:$D$2000,A38) -> 0 | N38: hcma, recruitment, salary, kontrak kerja, hc policy, hc maturity, working contract, employer branding, well-being, wellbeing, hc policies
A39: ADHOC-CMP | B39: Ad hoc request: Compliance | C39: Compliance | D39: BRI Pusat | E39: Ad hoc | G39: Stesya | H39: 11 | I39: Feb, Jul, Aug, Sep, Oct | J39: pak dicki | K39: =COUNTIF(Master!$D$2:$D$2000,A39) -> 0 | L39: No fixed owner: least-busy person in division
A40: ADHOC-PR | B40: Ad hoc request: Policy and Risk | C40: Policy and Risk | D40: Internal | E40: Ad hoc | G40: Stesya | H40: 16 | I40: Jul, Aug, Oct | J40: Email Mba Restu & Rafa | K40: =COUNTIF(Master!$D$2:$D$2000,A40) -> 0 | L40: No fixed owner: least-busy person in division
...

Sheet LetterCodes
A1: Letter code | B1: Route to division | C1: Times seen | D1: Divisions seen | E1: Example letter no. | F1: Confirmed by manager?
A2: DIR/ASQ | B2: Audit | C2: 2 | D2: Audit | E2: R.44.e-DIR/ASQ/10/2026
A3: DIR/SBM | B3: Finance | C3: 1 | D3: Finance | E3: R.5155-DIR/SBM/09/2026
A4: EMR/IRM | B4: Policy and Risk | C4: 6 | D4: Policy and Risk | E4: B.73.e-EMR/IRM/09/2026
A5: IDR/KEP | B5: Compliance | C5: 1 | D5: Compliance | E5: R.11-IDR/KEP/IGD/08/2026
A6: KEP/ING | B6: Compliance | C6: 1 | D6: Compliance | E6: B. 24 -KEP/ING/IGD/09/2026
A7: SBM/CMI | B7: Compliance | C7: 1 | D7: Compliance | E7: Nota Dinas SBM No. R.54.e-SBM/CMI/07/2026
A8: SBM/GVD | B8: Compliance | C8: 1 | D8: Compliance | E8: B.44.e-SBM/GVD/09/2026
A9: SBM/SNG | B9: Compliance | C9: 4 | D9: Compliance, Finance | E9: B.275.e-SBM/SNG/10/2026

Sheet AuditLog
A1: Timestamp | B1: User | C1: Task ID | D1: Action | E1: Field | F1: Old value | G1: New value | H1: Reason
A2: Filled automatically by the app. Do not edit by hand.

Sheet Config
A1: Setting | B1: Value | C1: What it does
A2: Effort: Small | B2: 1 | C2: Workload weight of a Small task (PRD scale or set by hand)
A3: Effort: Medium | B3: 2 | C3: Weight of a Medium task. Tasks with no effort set count as Medium
A4: Effort: Large | B4: 4 | C4: Weight of a Large task
A5: Support share | B5: 0.5 | C5: A supporting person carries this share of the task weight
A6: Overload threshold | B6: 10 | C6: Weighted open load above this = propose the backup instead (to be tuned)
A7: Stale after (days) | B7: 5 | C7: In Progress with no update for this many days = stale alert
A8: Reminder time | B8: 09:00 | C8: Daily digest email time (Hong Kong)
A9: Leaving warning (days) | B9: 30 | C9: Warn this many days before an intern's end date if they still own reports
A10: Unknown letter code | B10: Needs review | C10: What routing does when a letter code is not in LetterCodes
A11: Manager email | C11: Gets the daily approval + overdue digest. Fill in.
A12: Allowed email domain | C12: Only people with this email domain can log tasks via Chat, e.g. bri.co.id. Fill in.
A13: Gmail intake label | B13: GRC/To log | C13: Emails with this Gmail label become tasks
A14: Gmail done label | B14: GRC/Logged | C14: Applied after an email is logged
A15: Recurring lead (days) | B15: 14 | C15: Recurring reports are created this many days before their due date
A16: Default due (days) | B16: 7 | C16: Due date used when none is found in the message
A18: Notes
A19: Yellow = to confirm or fill in. Blue numbers = settings you can change; formulas in Master and Staff read them.
A20: Name merges: Ste/Stes→Stesya, Ve/Lovenya→Venya, Kak Leila→Leila, Sel/Seline→Selina, Ci→Cia, Pak Dicki→Dicki, Adel→Adeline, Hil→Hillary, Pak Ben→Ben.
A21: Guesses to check: Lovenya = Venya, Adel = Adeline, Hil = Hillary. Cynthia, Cindy and Cia are kept as three people.
A22: Assignee "All" or "GRC" = Whole team: Yes, no owner. PRD assessments are put under Policy and Risk (check).
A23: Status is simplified to Not Started / In Progress / On Hold / Done ("DONE & SUBMITTED" → Done).
A24: Effort and Weight are new: only PRD rows have an effort today; everything else defaults to Medium.
A25: Master starts empty except three [EXAMPLE] rows (status Done, so they do not count toward load). Delete them before go-live.
A26: Catalog owners, backups and due days were learned from the Jan–Oct 2026 tabs, which stay in the old file as an archive.
A27: Status "Proposed" = the script suggested an owner; the manager changes it to Not Started to approve. "Cancelled" = dropped on purpose.
